### 用一句话描述 try catch 能捕获到哪些 JS 异常

能捕捉到的异常，必须是线程执行已经进入 try catch 但 try catch 未执行完的时候抛出来的。



### try-catch之前

- 语法异常

  语法异常是在语法检查阶段就报错了，线程执行尚未进入 try catch 代码块，自然就无法捕获到异常。

### try-catch之中

### try-catch之后

- 异步报错

  代码报错的时候，线程已经执行完 try catch，这种不能捕捉到异常。

  ```js
  try{    
      setTimeout(()=>{         
          console.log(a.b);      
      }, 100)
  }catch(e){       	
      console.log('error',e);
  }
  console.log(111); 
  //output 
  111
  Uncaught ReferenceError: a is not defined
  ```

  

### 异常捕获方法

- window.onError

- Promise 

  reject和链式调用catch，因为内部已经catch error，外部try...catch无法捕获

- async/await

  try...catch。async/await实际是promise + generator，generator部分是同步代码。







### 异步报错为什么捕获不了

函数调用栈，如果没有捕获错误，错误会一层层传递到上一个执行环境，传递到全局都没有捕获，就报出来了。执行setTimeout回调的时候，之前的调用栈已经清空了（try...catch已经执行完了），所以直接报到全局。

